Workbook

Sheet 測試回報清單
A1: No. | B1: (公會) 回報日期 | C1: (公會) 回報人員 | D1: (公會) 問題說明 (請儘量詳述操作步驟或使用的測試資料, 以利開發人員還原問題除錯) | E1: 特殊活動說明無法移除 | F1: 版本 | G1: 測試帳號 | H1: 狀態 | I1: Priority | J1: 處理人員 | K1: Syscom備註 | L1: Syscom預計調整完成日 | M1: 預計提供 UAT日期 | N1: 實際完成 | O1: 上版日期 | P1: 覆驗/處理/回覆日期 | Q1: 覆驗/處理/回覆人員 | R1: 覆驗/處理/回覆狀況說明 | S1: 公會複驗通過 完成日期 | T1: 備註
A2: =IF(B2="","",ROW(B2)-1) -> 1 | B2: 45139 | C2: 郭副祕 | D2: 這是測試用的訊息 | G2: admin | H2: Cancel | I2: 中
A3: =IF(B3="","",ROW(B3)-1) -> 2 | B3: 45138 | C3: Ariel | D3: 學分計算效能優化 | H3: Close | I3: 中 | J3: Ariel | K3: 已優化完畢，40萬筆資料可正常計算 | O3: 45141
A4: =IF(B4="","",ROW(B4)-1) -> 3 | B4: 45138 | C4: 雙週會 | D4: 活動收據左下角加上經手人章(建課程/活動者) | H4: 覆驗通過 | I4: 中 | J4: Samuel/Brain | T4: 這頁的link無法查詢, 故無法測試
A5: =IF(B5="","",ROW(B5)-1) -> 4 | B5: 45138 | C5: 雙週會 | D5: 活動收據增加印花總繳的浮水印章壓在收執聯字樣附近，此項目僅需全聯會 | H5: Close | I5: 中 | J5: Samuel/Brain
A6: =IF(B6="","",ROW(B6)-1) -> 5 | B6: 45138 | C6: 雙週會 | D6: 因應檔案正確性問題取消地方公會課程直接打到全聯會方式，轉由匯入處理 匯入範例的活動與課程分頁，要加金額欄位(非必填)，若無就是免費，有的話課程結束後讓全聯會/會計師可以印收據 承上，付款日期統一為匯入日期，繳款自動轉為現金，印花稅也以匯入日期算 | H6: Close | I6: 中 | J6: Samuel/Ariel
A7: =IF(B7="","",ROW(B7)-1) -> 6 | B7: 45138 | C7: 雙週會 | D7: 月結事務所在課程結束後學分就可以勾稽，不用等到結清 | H7: Close | I7: 中 | J7: Ariel | K7: 目前只要上完課就會自動勾稽
A8: =IF(B8="","",ROW(B8)-1) -> 7 | B8: 45146 | C8: 教學 | D8: 全聯會執業會員異動的退會改為是學分不足的廢止，狀態中文寫為"廢止(金管會)" 執業登記變更的廢止則是不幹了的那種會計師(不用改) | G8: admin | H8: Close | I8: 中 | J8: Henry | P8: 45219 | R8: 欄位有增加，會計師明細資料欄位有問題，須修正欄位字眼
A9: =IF(B9="","",ROW(B9)-1) -> 8 | B9: 45146 | C9: 教學 | D9: 清單的會籍狀態改為執登狀態 | H9: Close | I9: 中 | J9: Ariel
A10: =IF(B10="","",ROW(B10)-1) -> 9 | B10: 45146 | C10: 黃宜婷 | D10: 非執業會員也需要可以報名上課，有自己的帳號可以繳會費等 | H10: Phase2 | K10: 難度較高為CR
A11: =IF(B11="","",ROW(B11)-1) -> 10 | B11: 45146 | C11: 教學 | D11: 上傳印鑑卡要加註時間日期才能知道什麼時候更新 | H11: Close | I11: 中 | J11: Ariel | P11: 45219 | R11: 將"最後異動日期"修正成登錄日期，日期以最新的為最上層
A12: =IF(B12="","",ROW(B12)-1) -> 11 | B12: 45146 | C12: 教學 | D12: 學分登記表最下方的斷行可以拉回去 1.承辦公開發行公司財務簽證之會計師，每年須進修第四條第一、二款(全聯會專教會講習)14小時，第三~九款合 計26 | H12: Close | I12: 中 | J12: Ariel
A13: =IF(B13="","",ROW(B13)-1) -> 12 | B13: 45146 | C13: 教學 | D13: 預查功能：事務所廢止一年內也要可以被查出來 | H13: Close | I13: 中 | J13: Henry
A14: =IF(B14="","",ROW(B14)-1) -> 13 | B14: 45146 | C14: 教學 | D14: 預查登錄的模組，新增/編輯的"原事務所名稱"改成使用下拉選單(跟事務所管理一樣) | H14: Close | I14: 中 | J14: Henry
A15: =IF(B15="","",ROW(B15)-1) -> 14 | B15: 45155 | C15: 薇伊 | D15: 活動與課程管理中-學員學分編輯查詢-裡面的最後編輯時間要修改成"課程日期(起跟迄)" | H15: Close | I15: 中 | J15: Ariel
A16: =IF(B16="","",ROW(B16)-1) -> 15 | B16: 45155 | C16: 薇伊 | D16: 活動與課程管理中-學分登記表-"會籍"那邊要加一個全部的選項; 拿掉會籍編號的預設數字 | H16: Close | I16: 中 | J16: Ariel
A17: =IF(B17="","",ROW(B17)-1) -> 16 | B17: 45155 | C17: 薇伊 | D17: 會計師持續進修小時登記表-課程日期上加上(民國年) | H17: Close | I17: 中 | J17: Ariel
A18: =IF(B18="","",ROW(B18)-1) -> 17 | B18: 45155 | C18: 薇伊 | D18: "學分匯入"的EXCEL檔: 1.兩個分頁都要增加承辦單位,必填但不要求填入完整全銜. 2.課程那分頁的講師改成非必填. 3.名單頁的報到時間拿掉,由系統取中間值. 4.由此學分匯入的講師,不要進入專教會的講師庫. 5.學分數也要落入檢定範圍. 6.本檔案匯入時,請提供排除重複的防呆警告. 7.檔案匯入後,要跳到學分編輯頁面. | H18: Close | I18: 中 | J18: Ariel
A19: =IF(B19="","",ROW(B19)-1) -> 18 | B19: 45156 | C19: 雙週會 | D19: 活動收據的事務所與會計師文字要對調 改為 OOO 會計師 XXXXXXXX事務所 | H19: Close | I19: 中 | J19: Ariel
A20: =IF(B20="","",ROW(B20)-1) -> 19 | B20: 45156 | C20: 教學 | D20: 全聯會一、二字第來文機關不能自填，影響後面報表，欄位改為可更改 | H20: Close | I20: 中 | J20: Henry
A21: =IF(B21="","",ROW(B21)-1) -> 20 | B21: 45159 | C21: 教學2 | D21: 活動的附件上傳，調整為可以上傳5個檔案，每個限制檔案10MB | H21: Close | I21: 中 | J21: Brian
A22: =IF(B22="","",ROW(B22)-1) -> 21 | B22: 45159 | C22: 教學2 | D22: 前台[我的課程與活動] 顯示的排序邏輯如果開始報名內的排序要調整為活動日期靠近得先排 例如已報名優先，再來是活動日期靠近的 | G22: 活動日期靠近的是在後面，點“即將到來”是靠近的日期在後面，“活動與課程”也一樣 | H22: Close | I22: 低 | J22: Tim | K22: 現在已經可點選近到遠或是遠到近做排序了
A23: =IF(B23="","",ROW(B23)-1) -> 22 | B23: 45159 | C23: 教學2 | D23: 講師模組：新增/編輯除了名字都是非必填 | H23: Close | I23: 中
A24: =IF(B24="","",ROW(B24)-1) -> 23 | B24: 45159 | C24: 教學2 | H24: Close | I24: 中 | J24: Ariel
A25: =IF(B25="","",ROW(B25)-1) -> 24 | B25: 45159 | C25: 教學2 | D25: 優惠券新增時要去抓身份證字號(現在抓成北市會編)，並且要加匯入功能 | H25: Close | I25: 中 | J25: Ariel
A26: =IF(B26="","",ROW(B26)-1) -> 25 | B26: 45159 | C26: 教學2 | H26: 待覆驗 | I26: 中 | J26: Ariel
A27: =IF(B27="","",ROW(B27)-1) -> 26 | B27: 45159 | C27: 教學2 | D27: 優惠券一個年度只能發一次，新增/匯入檢查時發現該年度已經發過要擋掉 | H27: Close | I27: 中 | J27: Ariel
A28: =IF(B28="","",ROW(B28)-1) -> 27 | B28: 45159 | C28: 教學2 | D28: 第一頁學分登記公文的地址要切齊姓名，整體對齊roccpa的r字 9/4目前僅有姓名對齊,地址仍未對齊roccpa的r | H28: Close | I28: 中 | J28: Ariel
A29: =IF(B29="","",ROW(B29)-1) -> 28 | B29: 45159 | C29: 教學2 | D29: 進修時數登記表的查詢介面，要多一個向下排除的勾勾，有的話查詢時就要向下排除地方公會(省公會>...) | H29: Close | I29: 中 | J29: Ariel | K29: 8/24: 查詢介面新增”排除會籍“。 ex: 若會籍勾選“台灣省”，排除會籍勾選"台北市"，需要查出所有台灣省會籍的會員中不包含台北市會籍的會員
A30: =IF(B30="","",ROW(B30)-1) -> 29 | B30: 45159 | C30: 教學2 | D30: 抵用券在報名過程中沒有成功被勾消(會務/會員) -扣法為扣一千&不找零，月結也可以抵 -一次最多只能用一張優惠券 -課堂金額為1000才能使用 | H30: Close | I30: 低 | J30: Ariel
A31: =IF(B31="","",ROW(B31)-1) -> 30 | B31: 45159 | C31: 教學2 | D31: menu要可以直接到助理人員清單內(不鎖事務所) | H31: Close | I31: 中 | J31: Alan
A32: =IF(B32="","",ROW(B32)-1) -> 31 | B32: 45159 | C32: 教學2 | D32: 助理人員清單頁要有身分證字號 | H32: Close | I32: 中 | J32: Alan
A33: =IF(B33="","",ROW(B33)-1) -> 32 | B33: 45159 | C33: 教學2 | D33: 收文要多一個收文型態 有全聯會一字第 二字第 三字第 還有一般的(沒字號)，可參考發文全聯會自第一二三做法 | H33: Close | I33: 低 | J33: Tim
A34: =IF(B34="","",ROW(B34)-1) -> 33 | B34: 45159 | C34: 教學2 | D34: 在助理人員送件的畫面，附件上傳多一個sample可以下載(全聯會提供空白檔) | H34: Close | I34: 中 | J34: Alan
A35: =IF(B35="","",ROW(B35)-1) -> 34 | B35: 45159 | C35: 教學2 | D35: 助理上傳要做檔案大小判定，不可超過perfomance界線 | H35: Close | I35: 中 | J35: Alan
A36: =IF(B36="","",ROW(B36)-1) -> 35 | B36: 45159 | C36: 教學2 | D36: 助理送件的email非必填 | G36: 09/23覆驗為必填選項 | H36: Close | I36: 低 | J36: Alan | K36: 第二審 沒有email 報錯的bug也已修正
A37: =IF(B37="","",ROW(B37)-1) -> 36 | B37: 45159 | C37: 教學2 | D37: 助理公文完要可以指派或是自動指派 | H37: Close | I37: 中 | J37: Alan
A38: =IF(B38="","",ROW(B38)-1) -> 37 | B38: 45159 | C38: 林香如 | D38: 優惠券要能設定期限 | H38: Phase2
A39: =IF(B39="","",ROW(B39)-1) -> 38 | B39: 45162 | C39: 省公會黃總幹事 | D39: 全聯會要有功能可以查詢各會計師加入地方公會的數字 例如加入北市 XX人，加入北市與省公會XX人... | H39: Phase2
A40: =IF(B40="","",ROW(B40)-1) -> 39 | B40: 45162 | C40: 郭副祕 | D40: 公文簽收表調整匹配全聯會 | H40: Phase2
...

Sheet 定義
A1: Bug分級定義 | F1: 總Bug數量 | G1: 待修正/處理中/覆驗失敗 | H1: 待覆驗 | I1: Close/Cancel/覆驗通過
A2: Critial | B2: 嚴重影響產品使用，系統支援問題，安全性問題 | F2: 最高 | G2: =countifs('測試回報清單'!$I:$I,$F2,'測試回報清單'!$H:$H,"待修正")+countifs('測試回報清單'!$I:$I,$F2,'測試回報清單'!$H:$H,"處理中")+countifs('測試回報清單'!$I:$I,$F2,'測試回報清單'!$H:$H,"覆驗失敗") -> 0 | H2: =countifs('測試回報清單'!$I:$I,$F2,'測試回報清單'!$H:$H,"待覆驗") -> 0 | I2: =countifs('測試回報清單'!$I:$I,$F2,'測試回報清單'!$H:$H,"Close")+countifs('測試回報清單'!$I:$I,$F2,'測試回報清單'!$H:$H,"Cancel")+countifs('測試回報清單'!$I:$I,$F2,'測試回報清單'!$H:$H,"覆驗通過") -> 0
A3: High | B3: 功能不符合流程且不能往下執行，且有效能問題 | F3: 高 | G3: =countifs('測試回報清單'!$I:$I,$F3,'測試回報清單'!$H:$H,"待修正")+countifs('測試回報清單'!$I:$I,$F3,'測試回報清單'!$H:$H,"處理中")+countifs('測試回報清單'!$I:$I,$F3,'測試回報清單'!$H:$H,"覆驗失敗") -> 0 | H3: =countifs('測試回報清單'!$I:$I,$F3,'測試回報清單'!$H:$H,"待覆驗") -> 1 | I3: =countifs('測試回報清單'!$I:$I,$F3,'測試回報清單'!$H:$H,"Close")+countifs('測試回報清單'!$I:$I,$F3,'測試回報清單'!$H:$H,"Cancel")+countifs('測試回報清單'!$I:$I,$F3,'測試回報清單'!$H:$H,"覆驗通過") -> 1
A4: Mid | B4: 不影響主流程, 但功能錯誤, 或缺少必要欄位 | F4: 中 | G4: =countifs('測試回報清單'!$I:$I,$F4,'測試回報清單'!$H:$H,"待修正")+countifs('測試回報清單'!$I:$I,$F4,'測試回報清單'!$H:$H,"處理中")+countifs('測試回報清單'!$I:$I,$F4,'測試回報清單'!$H:$H,"覆驗失敗") -> 0 | H4: =countifs('測試回報清單'!$I:$I,$F4,'測試回報清單'!$H:$H,"待覆驗") -> 3 | I4: =countifs('測試回報清單'!$I:$I,$F4,'測試回報清單'!$H:$H,"Close")+countifs('測試回報清單'!$I:$I,$F4,'測試回報清單'!$H:$H,"Cancel")+countifs('測試回報清單'!$I:$I,$F4,'測試回報清單'!$H:$H,"覆驗通過") -> 93
A5: Low | B5: 一些UI/Wording問題，不影響功能 | F5: 低 | G5: =countifs('測試回報清單'!$I:$I,$F5,'測試回報清單'!$H:$H,"待修正")+countifs('測試回報清單'!$I:$I,$F5,'測試回報清單'!$H:$H,"處理中")+countifs('測試回報清單'!$I:$I,$F5,'測試回報清單'!$H:$H,"覆驗失敗") -> 4 | H5: =countifs('測試回報清單'!$I:$I,$F5,'測試回報清單'!$H:$H,"待覆驗") -> 7 | I5: =countifs('測試回報清單'!$I:$I,$F5,'測試回報清單'!$H:$H,"Close")+countifs('測試回報清單'!$I:$I,$F5,'測試回報清單'!$H:$H,"Cancel")+countifs('測試回報清單'!$I:$I,$F5,'測試回報清單'!$H:$H,"覆驗通過") -> 129
F9: Bug數量(10/23之前) | G9: 待修正/處理中/覆驗失敗 | H9: 待覆驗 | I9: Close/Cancel/覆驗通過
F10: 最高 | G10: =countifs('測試回報清單'!$I:$I,$F10,'測試回報清單'!$H:$H,"待修正",'測試回報清單'!B:B,"<"&"2023/10/23")+countifs('測試回報清單'!$I:$I,$F10,'測試回報清單'!$H:$H,"處理中",'測試回報清單'!B:B,"<"&"2023/10/23")+countifs('測試回報清單'!$I:$I,$F10,'測試回報清單'!$H:$H,"覆驗失敗",'測試回報清單'!B:B,"<"&"2023/10/23") -> 0 | H10: =countifs('測試回報清單'!$I:$I,$F10,'測試回報清單'!$H:$H,"待覆驗",'測試回報清單'!B:B,"<"&"2023/10/23") -> 0 | I10: =countifs('測試回報清單'!$I:$I,$F10,'測試回報清單'!$H:$H,"Close",'測試回報清單'!B:B,"<"&"2023/10/23")+countifs('測試回報清單'!$I:$I,$F10,'測試回報清單'!$H:$H,"Cancel",'測試回報清單'!B:B,"<"&"2023/10/23")+countifs('測試回報清單'!$I:$I,$F10,'測試回報清單'!$H:$H,"覆驗通過",'測試回報清單'!B:B,"<"&"2023/10/23") -> 0
F11: 高 | G11: =countifs('測試回報清單'!$I:$I,$F11,'測試回報清單'!$H:$H,"待修正",'測試回報清單'!B:B,"<"&"2023/10/23")+countifs('測試回報清單'!$I:$I,$F11,'測試回報清單'!$H:$H,"處理中",'測試回報清單'!B:B,"<"&"2023/10/23")+countifs('測試回報清單'!$I:$I,$F11,'測試回報清單'!$H:$H,"覆驗失敗",'測試回報清單'!B:B,"<"&"2023/10/23") -> 0 | H11: =countifs('測試回報清單'!$I:$I,$F11,'測試回報清單'!$H:$H,"待覆驗",'測試回報清單'!B:B,"<"&"2023/10/23") -> 0 | I11: =countifs('測試回報清單'!$I:$I,$F11,'測試回報清單'!$H:$H,"Close",'測試回報清單'!B:B,"<"&"2023/10/23")+countifs('測試回報清單'!$I:$I,$F11,'測試回報清單'!$H:$H,"Cancel",'測試回報清單'!B:B,"<"&"2023/10/23")+countifs('測試回報清單'!$I:$I,$F11,'測試回報清單'!$H:$H,"覆驗通過",'測試回報清單'!B:B,"<"&"2023/10/23") -> 0
F12: 中 | G12: =countifs('測試回報清單'!$I:$I,$F12,'測試回報清單'!$H:$H,"待修正",'測試回報清單'!B:B,"<"&"2023/10/23")+countifs('測試回報清單'!$I:$I,$F12,'測試回報清單'!$H:$H,"處理中",'測試回報清單'!B:B,"<"&"2023/10/23")+countifs('測試回報清單'!$I:$I,$F12,'測試回報清單'!$H:$H,"覆驗失敗",'測試回報清單'!B:B,"<"&"2023/10/23") -> 0 | H12: =countifs('測試回報清單'!$I:$I,$F12,'測試回報清單'!$H:$H,"待覆驗",'測試回報清單'!B:B,"<"&"2023/10/23") -> 2 | I12: =countifs('測試回報清單'!$I:$I,$F12,'測試回報清單'!$H:$H,"Close",'測試回報清單'!B:B,"<"&"2023/10/23")+countifs('測試回報清單'!$I:$I,$F12,'測試回報清單'!$H:$H,"Cancel",'測試回報清單'!B:B,"<"&"2023/10/23")+countifs('測試回報清單'!$I:$I,$F12,'測試回報清單'!$H:$H,"覆驗通過",'測試回報清單'!B:B,"<"&"2023/10/23") -> 88
F13: 低 | G13: =countifs('測試回報清單'!$I:$I,$F13,'測試回報清單'!$H:$H,"待修正",'測試回報清單'!B:B,"<"&"2023/10/23")+countifs('測試回報清單'!$I:$I,$F13,'測試回報清單'!$H:$H,"處理中",'測試回報清單'!B:B,"<"&"2023/10/23")+countifs('測試回報清單'!$I:$I,$F13,'測試回報清單'!$H:$H,"覆驗失敗",'測試回報清單'!B:B,"<"&"2023/10/23") -> 1 | H13: =countifs('測試回報清單'!$I:$I,$F13,'測試回報清單'!$H:$H,"待覆驗",'測試回報清單'!B:B,"<"&"2023/10/23") -> 1 | I13: =countifs('測試回報清單'!$I:$I,$F13,'測試回報清單'!$H:$H,"Close",'測試回報清單'!B:B,"<"&"2023/10/23")+countifs('測試回報清單'!$I:$I,$F13,'測試回報清單'!$H:$H,"Cancel",'測試回報清單'!B:B,"<"&"2023/10/23")+countifs('測試回報清單'!$I:$I,$F13,'測試回報清單'!$H:$H,"覆驗通過",'測試回報清單'!B:B,"<"&"2023/10/23") -> 59

Sheet 測試注意事項
A1: 1.會籍管理新增會員及使用者管理新增帳號時，請填寫測試者自己的email，以便接收密碼信。
A2: 2.印鑑證明申請使用測試線上支付繳款時，請使用line pay掃描後，選擇取消付款即可測試繳款成功。
